<?xml version="1.0" encoding="utf-8"?>
<!-- This URDF was automatically created by SolidWorks to URDF Exporter! Originally created by Stephen Brawner (brawner@gmail.com) 
     Commit Version: 1.6.0-4-g7f85cfe  Build Version: 1.6.7995.38578
     For more information, please see http://wiki.ros.org/sw_urdf_exporter -->
<robot
  name="scara_description">
  <link
    name="base_link">
    <inertial>
      <origin
        xyz="0.0057621332343482 0.00285775270200555 0.193189380051916"
        rpy="0 0 0" />
      <mass
        value="0.57217968365953" />
      <inertia
        ixx="0.0124278422911613"
        ixy="4.96126683289887E-05"
        ixz="-0.000724082970449908"
        iyy="0.0130268328944623"
        iyz="0.000255561135289622"
        izz="0.000728269847627912" />
    </inertial>
    <visual>
      <origin
        xyz="0 0 0"
        rpy="0 0 0" />
      <geometry>
        <mesh
          filename="package://scara_description/meshes/base_link.STL" />
      </geometry>
      <material
        name="">
        <color
          rgba="0.792156862745098 0.819607843137255 0.933333333333333 1" />
      </material>
    </visual>
    <collision>
      <origin
        xyz="0 0 0"
        rpy="0 0 0" />
      <geometry>
        <mesh
          filename="package://scara_description/meshes/base_link.STL" />
      </geometry>
    </collision>
  </link>
  <link
    name="link1">
    <inertial>
      <origin
        xyz="0.0138321265029742 0.0695548003003947 0.124171706108288"
        rpy="0 0 0" />
      <mass
        value="0.27252514896887" />
      <inertia
        ixx="0.000571622269742261"
        ixy="1.08172931699114E-06"
        ixz="-1.42679992540951E-06"
        iyy="0.000398558077561348"
        iyz="-0.000118201456526435"
        izz="0.000667634937011231" />
    </inertial>
    <visual>
      <origin
        xyz="0 0 0"
        rpy="0 0 0" />
      <geometry>
        <mesh
          filename="package://scara_description/meshes/link1.STL" />
      </geometry>
      <material
        name="">
        <color
          rgba="0.792156862745098 0.819607843137255 0.933333333333333 1" />
      </material>
    </visual>
    <collision>
      <origin
        xyz="0 0 0"
        rpy="0 0 0" />
      <geometry>
        <mesh
          filename="package://scara_description/meshes/link1.STL" />
      </geometry>
    </collision>
  </link>
  <joint
    name="joint1"
    type="prismatic">
    <origin
      xyz="0 0 0"
      rpy="0 0 0" />
    <parent
      link="base_link" />
    <child
      link="link1" />
    <axis
      xyz="0 0 -1" />
    <limit
      lower="-0.25245"
      upper="0"
      effort="200"
      velocity="3" />
  </joint>
  <link
    name="link2">
    <inertial>
      <origin
        xyz="0.151219366961841 2.77555756156289E-17 0.0335829435916624"
        rpy="0 0 0" />
      <mass
        value="0.580917463575827" />
      <inertia
        ixx="0.000327730819903859"
        ixy="-9.67593407106374E-20"
        ixz="0.000146927246084188"
        iyy="0.00436977800756494"
        iyz="2.49232979655035E-19"
        izz="0.00450856517326053" />
    </inertial>
    <visual>
      <origin
        xyz="0 0 0"
        rpy="0 0 0" />
      <geometry>
        <mesh
          filename="package://scara_description/meshes/link2.STL" />
      </geometry>
      <material
        name="">
        <color
          rgba="0.792156862745098 0.819607843137255 0.933333333333333 1" />
      </material>
    </visual>
    <collision>
      <origin
        xyz="0 0 0"
        rpy="0 0 0" />
      <geometry>
        <mesh
          filename="package://scara_description/meshes/link2.STL" />
      </geometry>
    </collision>
  </link>
  <joint
    name="joint2"
    type="revolute">
    <origin
      xyz="0.014 0.0935 0.1372"
      rpy="0 0 0" />
    <parent
      link="link1" />
    <child
      link="link2" />
    <axis
      xyz="0 0 1" />
    <limit
      lower="-0.7854"
      upper="1.7977"
      effort="200"
      velocity="3" />
  </joint>
  <link
    name="link3">
    <inertial>
      <origin
        xyz="-1.38777878078145E-17 0.120570098997035 0.0414479064127798"
        rpy="0 0 0" />
      <mass
        value="0.300947531370299" />
      <inertia
        ixx="0.00309266769969678"
        ixy="-1.12554934406237E-19"
        ixz="-1.51741714335356E-20"
        iyy="0.00016611302475049"
        iyz="-0.000174741077577407"
        izz="0.00302343360822394" />
    </inertial>
    <visual>
      <origin
        xyz="0 0 0"
        rpy="0 0 0" />
      <geometry>
        <mesh
          filename="package://scara_description/meshes/link3.STL" />
      </geometry>
      <material
        name="">
        <color
          rgba="0.792156862745098 0.819607843137255 0.933333333333333 1" />
      </material>
    </visual>
    <collision>
      <origin
        xyz="0 0 0"
        rpy="0 0 0" />
      <geometry>
        <mesh
          filename="package://scara_description/meshes/link3.STL" />
      </geometry>
    </collision>
  </link>
  <joint
    name="joint3"
    type="revolute">
    <origin
      xyz="0.215 0 0.0453999999999997"
      rpy="0 0 -1.5707963267949" />
    <parent
      link="link2" />
    <child
      link="link3" />
    <axis
      xyz="0 0 1" />
    <limit
      lower="-2.618"
      upper="2.618"
      effort="200"
      velocity="3" />
  </joint>
  <link
    name="link4">
    <inertial>
      <origin
        xyz="0.000911907177548854 -0.0674185686260867 0.0693671054879262"
        rpy="0 0 0" />
      <mass
        value="0.161315962203164" />
      <inertia
        ixx="0.00040056998946175"
        ixy="-4.10216369660939E-06"
        ixz="4.75822222243618E-06"
        iyy="0.000252675454451169"
        iyz="0.000142989851619656"
        izz="0.000199381329691318" />
    </inertial>
    <visual>
      <origin
        xyz="0 0 0"
        rpy="0 0 0" />
      <geometry>
        <mesh
          filename="package://scara_description/meshes/link4.STL" />
      </geometry>
      <material
        name="">
        <color
          rgba="0.792156862745098 0.819607843137255 0.933333333333333 1" />
      </material>
    </visual>
    <collision>
      <origin
        xyz="0 0 0"
        rpy="0 0 0" />
      <geometry>
        <mesh
          filename="package://scara_description/meshes/link4.STL" />
      </geometry>
    </collision>
  </link>
  <joint
    name="joint4"
    type="revolute">
    <origin
      xyz="0 0.285 0.0416"
      rpy="0 0 -1.5707963267949" />
    <parent
      link="link3" />
    <child
      link="link4" />
    <axis
      xyz="0 0 1" />
    <limit
      lower="-2.6698"
      upper="3.0025"
      effort="200"
      velocity="3" />
  </joint>
  <link
    name="link5">
    <inertial>
      <origin
        xyz="0.00605536000839357 -0.00127524114842326 0.0394789472938122"
        rpy="0 0 0" />
      <mass
        value="0.158985625581691" />
      <inertia
        ixx="9.24577513113223E-05"
        ixy="-1.5445864125732E-06"
        ixz="-7.96961415230022E-07"
        iyy="0.000134712959630509"
        iyz="3.89855502623123E-06"
        izz="0.000119738799533511" />
    </inertial>
    <visual>
      <origin
        xyz="0 0 0"
        rpy="0 0 0" />
      <geometry>
        <mesh
          filename="package://scara_description/meshes/link5.STL" />
      </geometry>
      <material
        name="">
        <color
          rgba="0.792156862745098 0.819607843137255 0.933333333333333 1" />
      </material>
    </visual>
    <collision>
      <origin
        xyz="0 0 0"
        rpy="0 0 0" />
      <geometry>
        <mesh
          filename="package://scara_description/meshes/link5.STL" />
      </geometry>
    </collision>
  </link>
  <joint
    name="joint5"
    type="revolute">
    <origin
      xyz="0 -0.047 0.092"
      rpy="-1.5707963267949 0 0" />
    <parent
      link="link4" />
    <child
      link="link5" />
    <axis
      xyz="0 0 -1" />
    <limit
      lower="0.0"
      upper="0.69813"
      effort="200"
      velocity="3" />
  </joint>
  <link
    name="link6">
    <inertial>
      <origin
        xyz="-0.00355403590625505 -0.00251181168132289 -0.0510095609592032"
        rpy="0 0 0" />
      <mass
        value="0.0717968221721647" />
      <inertia
        ixx="5.56065583559543E-05"
        ixy="7.72628005861415E-07"
        ixz="-4.6344552032925E-06"
        iyy="4.79357175536453E-05"
        iyz="2.19980245329151E-07"
        izz="3.33722393714322E-05" />
    </inertial>
    <visual>
      <origin
        xyz="0 0 0"
        rpy="0 0 0" />
      <geometry>
        <mesh
          filename="package://scara_description/meshes/link6.STL" />
      </geometry>
      <material
        name="">
        <color
          rgba="0.792156862745098 0.819607843137255 0.933333333333333 1" />
      </material>
    </visual>
    <collision>
      <origin
        xyz="0 0 0"
        rpy="0 0 0" />
      <geometry>
        <mesh
          filename="package://scara_description/meshes/link6.STL" />
      </geometry>
    </collision>
  </link>
  <joint
    name="joint6"
    type="revolute">
    <origin
      xyz="-0.0178499999999999 0 0.048"
      rpy="1.5707963267949 0 1.5707963267949" />
    <parent
      link="link5" />
    <child
      link="link6" />
    <axis
      xyz="0 0 1" />
    <limit
      lower="-1.5708"
      upper="1.5708"
      effort="200"
      velocity="3" />
  </joint>
  <link
    name="link7">
    <inertial>
      <origin
        xyz="-0.0112224969341433 2.77555756156289E-17 -1.38777878078145E-17"
        rpy="0 0 0" />
      <mass
        value="0.0281299504553923" />
      <inertia
        ixx="4.36826634068471E-06"
        ixy="5.20286234456131E-21"
        ixz="1.71012922866411E-22"
        iyy="6.50865119427316E-06"
        iyz="1.1254987768263E-20"
        izz="4.81664015522416E-06" />
    </inertial>
    <visual>
      <origin
        xyz="0 0 0"
        rpy="0 0 0" />
      <geometry>
        <mesh
          filename="package://scara_description/meshes/link7.STL" />
      </geometry>
      <material
        name="">
        <color
          rgba="0.792156862745098 0.819607843137255 0.933333333333333 1" />
      </material>
    </visual>
    <collision>
      <origin
        xyz="0 0 0"
        rpy="0 0 0" />
      <geometry>
        <mesh
          filename="package://scara_description/meshes/link7.STL" />
      </geometry>
    </collision>
  </link>
  <joint
    name="joint7"
    type="revolute">
    <origin
      xyz="0 0 -0.078405"
      rpy="1.5708 -1.5708 0" />
    <parent
      link="link6" />
    <child
      link="link7" />
    <axis
      xyz="0 0 1" />
    <limit
      lower="-0.17453"
      upper="1.5708"
      effort="200"
      velocity="3" />
  </joint>
  <link
    name="link8">
    <inertial>
      <origin
        xyz="-0.0355732119020791 2.77555756156289E-17 9.71445146547012E-17"
        rpy="0 0 0" />
      <mass
        value="0.0374587379875856" />
      <inertia
        ixx="1.91779993839597E-05"
        ixy="-2.01711871875207E-20"
        ixz="-9.55306611337375E-21"
        iyy="1.01343765382842E-05"
        iyz="-9.83806034622694E-22"
        izz="1.01343765382842E-05" />
    </inertial>
    <visual>
      <origin
        xyz="0 0 0"
        rpy="0 0 0" />
      <geometry>
        <mesh
          filename="package://scara_description/meshes/link8.STL" />
      </geometry>
      <material
        name="">
        <color
          rgba="0.792156862745098 0.819607843137255 0.933333333333333 1" />
      </material>
    </visual>
    <collision>
      <origin
        xyz="0 0 0"
        rpy="0 0 0" />
      <geometry>
        <mesh
          filename="package://scara_description/meshes/link8.STL" />
      </geometry>
    </collision>
  </link>
  <joint
    name="joint8"
    type="fixed">
    <origin
      xyz="0 0 0"
      rpy="0 0 0" />
    <parent
      link="link7" />
    <child
      link="link8" />
    <axis
      xyz="0 0 0" />
  </joint>
</robot>